Workbook

Sheet Sentinel
A1: MINE | B1: SENTINEL FQM
A2: YEAR | B2: 2015 | C2: 2016 | D2: 2017 | E2: 2018 | F2: 2019 | G2: 2020 | H2: 2021 | I2: 2022 | J2: 2023 | K2: 2024
A3: Copper ore processed (000’s tonnes) | B3: 14016 | C3: 36369 | D3: 42087 | E3: 48750 | F3: 48858 | G3: 56589 | H3: 56329 | I3: 58868 | J3: 49221 | K3: 51300
A4: Copper ore grade processed (%) | B4: 0.6 | C4: 0.6 | D4: 0.5 | E4: 0.5 | F4: 0.5 | G4: 0.49 | H4: 0.47 | I4: 0.46 | J4: 0.49 | K4: 0.51
A5: Copper recovery (%) | B5: 41 | C5: 68 | D5: 87 | E5: 91 | F5: 91 | G5: 90 | H5: 89 | I5: 90 | J5: 90 | K5: 88
A6: Copper production (tonnes) | B6: 32971 | C6: 139600 | D6: 190683 | E6: 223656 | F6: 220006 | G6: 251216 | H6: 232688 | I6: 242451 | J6: 214046 | K6: 230792

Sheet Kansanshi
A1: MINE | B1: KANSANSHI
A2: YEAR | B2: 2015 | C2: 2016 | D2: 2017 | E2: 2018 | F2: 2019 | G2: 2020 | H2: 2021 | I2: 2022 | J2: 2023 | K2: 2024
A3: Sulphide ore tonnes milled(000's) | B3: 8296 | C3: 11988 | D3: 12970 | E3: 12978 | F3: 12908 | G3: 13527 | H3: 13386 | I3: 13160 | J3: 12446 | K3: 9452
A4: Sulphide ore grade processed(%) | B4: 0.8 | C4: 0.8 | D4: 0.8 | E4: 0.78 | F4: 0.89 | G4: 0.83 | H4: 0.88 | I4: 0.71 | J4: 0.51 | K4: 0.6
A5: Sulphide copper recovery(%) | B5: 91 | C5: 92 | D5: 91 | E5: 91 | F5: 91 | G5: 92 | H5: 91 | I5: 89 | J5: 88 | K5: 91
A6: Mixed ore tonnes milled(000's) | B6: 10949 | C6: 7953 | D6: 7997 | E6: 8186 | F6: 7699 | G6: 8167 | H6: 7601 | I6: 7713 | J6: 7773 | K6: 10061
A7: Mixed ore grade processed(%) | B7: 1.1 | C7: 1 | D7: 1 | E7: 1.06 | F7: 1.05 | G7: 1 | H7: 0.96 | I7: 0.63 | J7: 0.63 | K7: 0.98
A8: Mixed copper recovery(%) | B8: 72 | C8: 84 | D8: 85 | E8: 82 | F8: 77 | G8: 81 | H8: 82 | I8: 74 | J8: 71 | K8: 81
A9: Oxide ore tonnes milled(000's) | B9: 6795 | C9: 7076 | D9: 6916 | E9: 6916 | F9: 7201 | G9: 7440 | H9: 7164 | I9: 7866 | J9: 7232 | K9: 7404
A10: Oxide ore grade processed(%) | B10: 1.5 | C10: 1.5 | D10: 1.5 | E10: 1.44 | F10: 1.12 | G10: 0.93 | H10: 0.72 | I10: 0.57 | J10: 0.83 | K10: 0.74
A11: Oxide copper recovery(%) | B11: 80 | C11: 94 | D11: 87 | E11: 89 | F11: 82 | G11: 76 | H11: 69 | I11: 64 | J11: 76 | K11: 73
A12: Copper production (tonnes) | B12: 226674 | C12: 253272 | D12: 250801 | E12: 251522 | F12: 232243 | G12: 221487 | H12: 202159 | I12: 146282 | J12: 134827 | K12: 170929
A13: COPPER SMELTER
A14: Concentrate processed(DMT) | B14: 709188 | C14: 1143974 | D14: 1211740 | E14: 1381637 | F14: 1317826 | G14: 1320328 | H14: 1259856 | I14: 1304839 | J14: 1281364 | K14: 1356478
A15: Copper anodes produced(tonnes) | B15: 150292 | C15: 257330 | D15: 291553 | E15: 347037 | F15: 324281 | G15: 323667 | H15: 301556 | I15: 304914 | J15: 315860 | K15: 335500
A16: Smelter copper recovery(%) | B16: 98 | C16: 97 | D16: 96 | E16: 97 | F16: 97 | G16: 98 | H16: 98 | I16: 97 | J16: 98 | K16: 97
A17: Acid tonnes produced(000's) | B17: 645 | C17: 1109 | D17: 1128 | E17: 1255 | F17: 1236 | G17: 1262 | H17: 1217 | I17: 1247 | J17: 1166 | K17: 1202

Sheet Total predictions and analysis
A2: PESSIMISTIC SCENARIO
A3: YEAR | B3: SENTINEL | C3: KANSANSHI | D3: FQM TOTAL
A4: 2024 | B4: 170929 | C4: 230792 | D4: =SUM(B4:C4) -> 401721
A5: 2025 | B5: 229540 | C5: 157828 | D5: =SUM(B5:C5) -> 387368
A6: 2026 | B6: 225997 | C6: 149551 | D6: =SUM(B6:C6) -> 375548
A7: 2027 | B7: 231660 | C7: 143288 | D7: =SUM(B7:C7) -> 374948
A8: 2028 | B8: 236038 | C8: 135799 | D8: =SUM(B8:C8) -> 371837
A9: 2029 | B9: 229427 | C9: 126454 | D9: =SUM(B9:C9) -> 355881
A10: 2030 | B10: 237460 | C10: 119483 | D10: =SUM(B10:C10) -> 356943
A11: 2031 | B11: 237460 | C11: 112887 | D11: =SUM(B11:C11) -> 350347
A15: BEST CASE SCENARIO
A16: YEAR | B16: SENTINEL | C16: KANSANSHI | D16: FQM TOTAL
A17: 2024 | B17: 170929 | C17: 230792 | D17: =SUM(B17:C17) -> 401721
A18: 2025 | B18: 235701 | C18: 177395 | D18: =SUM(B18:C18) -> 413096
A19: 2026 | B19: 238769 | C19: 186548 | D19: =SUM(B19:C19) -> 425317
A20: 2027 | B20: 242312 | C20: 202385 | D20: =SUM(B20:C20) -> 444697
A21: 2028 | B21: 247164 | C21: 118741 | D21: =SUM(B21:C21) -> 365905
A22: 2029 | B22: 250707 | C22: 222447 | D22: =SUM(B22:C22) -> 473154
A23: 2030 | B23: 253775 | C23: 226645 | D23: =SUM(B23:C23) -> 480420
A24: 2031 | B24: 253775 | C24: 231641 | D24: =SUM(B24:C24) -> 485416
A28: OPTIMISTIC SCENARIO
A29: YEAR | B29: SENTINEL | C29: KANSANSHI | D29: FQM TOTAL
A30: 2024 | B30: 170929 | C30: 230792 | D30: =SUM(B30:C30) -> 401721
A31: 2025 | B31: 244569 | C31: 211180 | D31: =SUM(B31:C31) -> 455749
A32: 2026 | B32: 248112 | C32: 230854 | D32: =SUM(B32:C32) -> 478966
A33: 2027 | B33: 253438 | C33: 253322 | D33: =SUM(B33:C33) -> 506760
A34: 2028 | B34: 256981 | C34: 276684 | D34: =SUM(B34:C34) -> 533665
A35: 2029 | B35: 262307 | C35: 302313 | D35: =SUM(B35:C35) -> 564620
A36: 2030 | B36: 265375 | C36: 330695 | D36: =SUM(B36:C36) -> 596070
A37: 2031 | B37: 269753 | C37: 354562 | D37: =SUM(B37:C37) -> 624315

Sheet General analysis 
I1: FQM CONTRIBUTION TO ZAMBIA TOTAL PRODUCTION(%)
A2: YEAR | B2: Zambias total production.(copper production tonnes) | C2: Kansanshi Copper production (tonnes) | D2: Sentinel Copper production (tonnes) | E2: FQM CONTRIBUTION TO ZAMBIA TOTAL PRODUCTION(%) | F2: Total production of kansanshi and sentinel | G2: PERCENTAGE CONTRIBUTION OF KANSANSHI | H2: PERCENTAGE CONTRIBUTION OF SENTINEL
A3: 2015 | B3: 710560 | C3: 226674 | D3: 32971 | E3: =(Sentinel!B6+Kansanshi!B12)/'General analysis '!B3 -> 0.36540897 | F3: =(C3+D3) -> 259645 | G3: =(C3/F3) -> 0.87301508 | H3: =(D3/F3) -> 0.12698492 | I3: Mean | J3: 0.51789166
A4: 2016 | B4: 770590 | C4: 253272 | D4: 139600 | E4: =(Sentinel!C6+Kansanshi!C12)/'General analysis '!B4 -> 0.50983273 | F4: =(C4+D4) -> 392872 | G4: =(C4/F4) -> 0.64466798 | H4: =(D4/F4) -> 0.35533202 | I4: Standard Error | J4: 0.020684159
A5: 2017 | B5: 786730 | C5: 250801 | D5: 190683 | E5: =(Sentinel!D6+Kansanshi!D12)/'General analysis '!B5 -> 0.5611633 | F5: =(C5+D5) -> 441484 | G5: =(C5/F5) -> 0.56808627 | H5: =(D5/F5) -> 0.43191373 | I5: Median | J5: 0.52542772
A6: 2018 | B6: 809840 | C6: 251522 | D6: 223656 | E6: =(Sentinel!E6+Kansanshi!E12)/'General analysis '!B6 -> 0.58675541 | F6: =(C6+D6) -> 475178 | G6: =(C6/F6) -> 0.52932164 | H6: =(D6/F6) -> 0.47067836 | I6: Mode | J6: #N/A
A7: 2019 | B7: 793900 | C7: 232243 | D7: 220006 | E7: =(Sentinel!F6+Kansanshi!F12)/'General analysis '!B7 -> 0.56965487 | F7: =(C7+D7) -> 452249 | G7: =(C7/F7) -> 0.51352905 | H7: =(D7/F7) -> 0.48647095 | I7: Standard Deviation | J7: 0.065409053
A8: 2020 | B8: 828950 | C8: 221487 | D8: 251216 | E8: =(Sentinel!G6+Kansanshi!G12)/'General analysis '!B8 -> 0.57024308 | F8: =(C8+D8) -> 472703 | G8: =(C8/F8) -> 0.46855425 | H8: =(D8/F8) -> 0.53144575 | I8: Sample Variance | J8: 0.0042783442
A9: 2021 | B9: 803750 | C9: 202159 | D9: 232688 | E9: =(Sentinel!H6+Kansanshi!H12)/'General analysis '!B9 -> 0.54102271 | F9: =(C9+D9) -> 434847 | G9: =(C9/F9) -> 0.46489685 | H9: =(D9/F9) -> 0.53510315 | I9: Kurtosis | J9: 2.6390936
A10: 2022 | B10: 763550 | C10: 146282 | D10: 242451 | E10: =(Sentinel!I6+Kansanshi!I12)/'General analysis '!B10 -> 0.5091127 | F10: =(C10+D10) -> 388733 | G10: =(C10/F10) -> 0.37630456 | H10: =(D10/F10) -> 0.62369544 | I10: Skewness | J10: -1.4589853
A11: 2023 | B11: 732580 | C11: 134827 | D11: 214046 | E11: =(Sentinel!J6+Kansanshi!J12)/'General analysis '!B11 -> 0.47622512 | F11: =(C11+D11) -> 348873 | G11: =(C11/F11) -> 0.38646442 | H11: =(D11/F11) -> 0.61353558 | I11: Range | J11: 0.22134644
A12: 2024 | B12: 820680 | C12: 170929 | D12: 230792 | E12: =(Sentinel!K6+Kansanshi!K12)/'General analysis '!B12 -> 0.48949773 | F12: =(C12+D12) -> 401721 | G12: =(C12/F12) -> 0.42549182 | H12: =(D12/F12) -> 0.57450818 | I12: Minimum | J12: 0.36540897
I13: Maximum | J13: 0.58675541
I14: Sum | J14: 5.1789166
A15: YEAR | B15: SENTINEL PERCENTAGE CONTRIBUTION TO ZAMBIA | C15: KANSANSHI PERCENTAGE CONTRIBUTION TO ZAMBIA | I15: Count | J15: 10
A16: 2015 | B16: =(D3/B3) -> 0.04640143 | C16: =C3/B3 -> 0.31900754
A17: 2016 | B17: =(D4/B4) -> 0.18115989 | C17: =C4/B4 -> 0.32867284
A18: 2017 | B18: =(D5/B5) -> 0.24237413 | C18: =C5/B5 -> 0.31878917
A19: 2018 | B19: =(D6/B6) -> 0.27617307 | C19: =C6/B6 -> 0.31058234
A20: 2019 | B20: =(D7/B7) -> 0.27712054 | C20: =C7/B7 -> 0.29253432
A21: 2020 | B21: =(D8/B8) -> 0.30305326 | C21: =C8/B8 -> 0.26718982
A22: 2021 | B22: =(D9/B9) -> 0.28950295 | C22: =C9/B9 -> 0.25151975
A23: 2022 | B23: =(D10/B10) -> 0.31753127 | C23: =C10/B10 -> 0.19158143
A24: 2023 | B24: =(D11/B11) -> 0.29218106 | C24: =C11/B11 -> 0.18404406
A25: 2024 | B25: =(D12/B12) -> 0.28122045 | C25: =C12/B12 -> 0.20827728
A30: Total production of kansanshi and sentinel | C30: PERCENTAGE CONTRIBUTION OF KANSANSHI | E30: PERCENTAGE CONTRIBUTION OF SENTINEL | G30: SENTINEL PERCENTAGE CONTRIBUTION TO ZAMBIA(%) | I30: KANSANSHI PERCENTAGE CONTRIBUTION TO ZAMBIA(%)
A32: Mean | B32: 406830.5 | C32: Mean | D32: 0.52503319 | E32: Mean | F32: 0.47496681 | G32: Mean | H32: 0.25067181 | I32: Mean | J32: 0.26721985
A33: Standard Error | B33: 20717.761 | C33: Standard Error | D33: 0.04660048 | E33: Standard Error | F33: 0.04660048 | G33: Standard Error | H33: 0.025680753 | I33: Standard Error | J33: 0.017638046
A34: Median | B34: 418284 | C34: Median | D34: 0.49104165 | E34: Median | F34: 0.50895835 | G34: Median | H34: 0.2791705 | I34: Median | J34: 0.27986207
A35: Mode | B35: #N/A | C35: Mode | D35: #N/A | E35: Mode | F35: #N/A | G35: Mode | H35: #N/A | I35: Mode | J35: #N/A
A36: Standard Deviation | B36: 65515.313 | C36: Standard Deviation | D36: 0.14736366 | E36: Standard Deviation | F36: 0.14736366 | G36: Standard Deviation | H36: 0.08120967 | I36: Standard Deviation | J36: 0.055776398
A37: Sample Variance | B37: 4.2922562e+09 | C37: Sample Variance | D37: 0.021716048 | E37: Sample Variance | F37: 0.021716048 | G37: Sample Variance | H37: 0.0065950106 | I37: Sample Variance | J37: 0.0031110066
A38: Kurtosis | B38: 1.9121647 | C38: Kurtosis | D38: 2.9966105 | E38: Kurtosis | F38: 2.9966105 | G38: Kurtosis | H38: 4.6880068 | I38: Kurtosis | J38: -1.5159882
A39: Skewness | B39: -1.2987699 | C39: Skewness | D39: 1.5881903 | E39: Skewness | F39: -1.5881903 | G39: Skewness | H39: -2.1325959 | I39: Skewness | J39: -0.48901467
A40: Range | B40: 215533 | C40: Range | D40: 0.49671052 | E40: Range | F40: 0.49671052 | G40: Range | H40: 0.27112984 | I40: Range | J40: 0.14462877
A41: Minimum | B41: 259645 | C41: Minimum | D41: 0.37630456 | E41: Minimum | F41: 0.12698492 | G41: Minimum | H41: 0.04640143 | I41: Minimum | J41: 0.18404406
A42: Maximum | B42: 475178 | C42: Maximum | D42: 0.87301508 | E42: Maximum | F42: 0.62369544 | G42: Maximum | H42: 0.31753127 | I42: Maximum | J42: 0.32867284
A43: Sum | B43: 4068305 | C43: Sum | D43: 5.2503319 | E43: Sum | F43: 4.7496681 | G43: Sum | H43: 2.5067181 | I43: Sum | J43: 2.6721985
A44: Count | B44: 10 | C44: Count | D44: 10 | E44: Count | F44: 10 | G44: Count | H44: 10 | I44: Count | J44: 10

Sheet Sentinel Predictions
B1: PESSIMISTIC PREDICTION
A2: YEAR | B2: Copper recovery (%) | C2: Copper ore grade processed (%) | D2: Copper ore processed (000’s tonnes) | E2: Predicted Copper production | F2: Lower Bound | G2: Upper Bound
A3: 2025 | B3: 88 | C3: 0.5 | D3: 53000 | E3: =-113731.2701 + (1783.343899*B3)+(47408.88358*C3)+(3.068533632*D3) -> 229539.72 | F3: =(E3)-(1.96*6980.736793) -> 215857.47 | G3: =(E3)+(1.96*6980.736793) -> 243221.96
A4: 2026 | B4: 88 | C4: 0.49 | D4: 52000 | E4: =-113731.2701 + (1783.343899*B4)+(47408.88358*C4)+(3.068533632*D4) -> 225997.09 | F4: =(E4)-(1.96*6980.736793) -> 212314.85 | G4: =(E4)+(1.96*6980.736793) -> 239679.34
A5: 2027 | B5: 88 | C5: 0.48 | D5: 54000 | E5: =-113731.2701 + (1783.343899*B5)+(47408.88358*C5)+(3.068533632*D5) -> 231660.07 | F5: =(E5)-(1.96*6980.736793) -> 217977.83 | G5: =(E5)+(1.96*6980.736793) -> 245342.32
A6: 2028 | B6: 89 | C6: 0.47 | D6: 55000 | E6: =-113731.2701 + (1783.343899*B6)+(47408.88358*C6)+(3.068533632*D6) -> 236037.86 | F6: =(E6)-(1.96*6980.736793) -> 222355.62 | G6: =(E6)+(1.96*6980.736793) -> 249720.11
A7: 2029 | B7: 89 | C7: 0.46 | D7: 53000 | E7: =-113731.2701 + (1783.343899*B7)+(47408.88358*C7)+(3.068533632*D7) -> 229426.71 | F7: =(E7)-(1.96*6980.736793) -> 215744.46 | G7: =(E7)+(1.96*6980.736793) -> 243108.95
A8: 2030 | B8: 89 | C8: 0.5 | D8: 55000 | E8: =-113731.2701 + (1783.343899*B8)+(47408.88358*C8)+(3.068533632*D8) -> 237460.13 | F8: =(E8)-(1.96*6980.736793) -> 223777.88 | G8: =(E8)+(1.96*6980.736793) -> 251142.37
A9: 2031 | B9: 89 | C9: 0.5 | D9: 55000 | E9: =-113731.2701 + (1783.343899*B9)+(47408.88358*C9)+(3.068533632*D9) -> 237460.13 | F9: =(E9)-(1.96*6980.736793) -> 223777.88 | G9: =(E9)+(1.96*6980.736793) -> 251142.37
A12: BEST CASE PREDICTION
A13: YEAR | B13: Copper recovery (%) | C13: Copper ore grade processed (%) | D13: Copper ore processed (000’s tonnes) | E13: Predicted Copper production | F13: Lower Bound | G13: Upper Bound
A14: 2025 | B14: 90 | C14: 0.49 | D14: 54000 | E14: =-113731.2701+(1783.343899*B14)+(47408.88358*C14)+(3.068533632*D14) -> 235700.85 | F14: =(E14)-(1.96*6980.74) -> 222018.6 | G14: =(E14)+(1.96*6980.74) -> 249383.1
A15: 2026 | B15: 90 | C15: 0.49 | D15: 55000 | E15: =-113731.2701+(1783.343899*B15)+(47408.88358*C15)+(3.068533632*D15) -> 238769.38 | F15: =(E15)-(1.96*6980.74) -> 225087.13 | G15: =(E15)+(1.96*6980.74) -> 252451.63
A16: 2027 | B16: 90 | C16: 0.5 | D16: 56000 | E16: =-113731.2701+(1783.343899*B16)+(47408.88358*C16)+(3.068533632*D16) -> 242312.01 | F16: =(E16)-(1.96*6980.74) -> 228629.76 | G16: =(E16)+(1.96*6980.74) -> 255994.26
A17: 2028 | B17: 91 | C17: 0.5 | D17: 57000 | E17: =-113731.2701+(1783.343899*B17)+(47408.88358*C17)+(3.068533632*D17) -> 247163.88 | F17: =(E17)-(1.96*6980.74) -> 233481.63 | G17: =(E17)+(1.96*6980.74) -> 260846.13
A18: 2029 | B18: 91 | C18: 0.51 | D18: 58000 | E18: =-113731.2701+(1783.343899*B18)+(47408.88358*C18)+(3.068533632*D18) -> 250706.51 | F18: =(E18)-(1.96*6980.74) -> 237024.26 | G18: =(E18)+(1.96*6980.74) -> 264388.76
A19: 2030 | B19: 91 | C19: 0.51 | D19: 59000 | E19: =-113731.2701+(1783.343899*B19)+(47408.88358*C19)+(3.068533632*D19) -> 253775.04 | F19: =(E19)-(1.96*6980.74) -> 240092.79 | G19: =(E19)+(1.96*6980.74) -> 267457.29
A20: 2031 | B20: 91 | C20: 0.51 | D20: 59000 | E20: =-113731.2701+(1783.343899*B20)+(47408.88358*C20)+(3.068533632*D20) -> 253775.04 | F20: =(E20)-(1.96*6980.74) -> 240092.79 | G20: =(E20)+(1.96*6980.74) -> 267457.29
A23: OPTIMISTIC PREDICTION
A24: YEAR | B24: Copper recovery (%) | C24: Copper ore grade processed (%) | D24: Copper ore processed (000’s tonnes) | E24: Predicted Copper production | F24: Lower Bound | G24: Upper Bound
A25: 2025 | B25: 91 | C25: 0.51 | D25: 56000 | E25: =-113731.2701+(1783.343899*B25)+(47408.88358*C25)+(3.068533632*D25) -> 244569.44 | F25: =(E25)-(1.96*6980.74) -> 230887.19 | G25: =(E25)+(1.96*6980.74) -> 258251.69
A26: 2026 | B26: 91 | C26: 0.52 | D26: 57000 | E26: =-113731.2701+(1783.343899*B26)+(47408.88358*C26)+(3.068533632*D26) -> 248112.06 | F26: =(E26)-(1.96*6980.74) -> 234429.81 | G26: =(E26)+(1.96*6980.74) -> 261794.31
A27: 2027 | B27: 92 | C27: 0.53 | D27: 58000 | E27: =-113731.2701+(1783.343899*B27)+(47408.88358*C27)+(3.068533632*D27) -> 253438.03 | F27: =(E27)-(1.96*6980.74) -> 239755.78 | G27: =(E27)+(1.96*6980.74) -> 267120.28
A28: 2028 | B28: 92 | C28: 0.54 | D28: 59000 | E28: =-113731.2701+(1783.343899*B28)+(47408.88358*C28)+(3.068533632*D28) -> 256980.65 | F28: =(E28)-(1.96*6980.74) -> 243298.4 | G28: =(E28)+(1.96*6980.74) -> 270662.9
A29: 2029 | B29: 93 | C29: 0.55 | D29: 60000 | E29: =-113731.2701+(1783.343899*B29)+(47408.88358*C29)+(3.068533632*D29) -> 262306.62 | F29: =(E29)-(1.96*6980.74) -> 248624.37 | G29: =(E29)+(1.96*6980.74) -> 275988.87
A30: 2030 | B30: 93 | C30: 0.55 | D30: 61000 | E30: =-113731.2701+(1783.343899*B30)+(47408.88358*C30)+(3.068533632*D30) -> 265375.15 | F30: =(E30)-(1.96*6980.74) -> 251692.9 | G30: =(E30)+(1.96*6980.74) -> 279057.4
A31: 2031 | B31: 94 | C31: 0.54 | D31: 62000 | E31: =-113731.2701+(1783.343899*B31)+(47408.88358*C31)+(3.068533632*D31) -> 269752.94 | F31: =(E31)-(1.96*6980.74) -> 256070.69 | G31: =(E31)+(1.96*6980.74) -> 283435.19

Sheet Kansanshi predictions
A2: OXIDE ORE PESSIMISTIC PREDICTION | H2: MIXED ORE PESSIMISTIC PREDICTION | O2: SULPHIDE ORE PESSIMISTIC PREDICTION
A3: Year | B3: Copper recovery (%) | C3: Copper ore grade processed (%) | D3: Copper ore processed (000’s tonnes) | E3: Predicted Production | H3: Year | I3: Copper recovery (%) | J3: Copper ore grade processed (%) | K3: Copper ore processed (000’s tonnes) | L3: Predicted Producton | O3: Year | P3: Copper recovery (%) | Q3: Copper ore grade processed (%) | R3: Copper ore processed (000’s tonnes) | S3: PREDICTED PRODUCTION
A4: 2025 | B4: 72 | C4: 0.72 | D4: 7300 | E4: =(B4*C4*D4*0.1) -> 37843.2 | H4: 2025 | I4: 78 | J4: 0.95 | K4: 9500 | L4: =(I4*J4*K4*0.1) -> 70395 | O4: 2025 | P4: 90 | Q4: 0.58 | R4: 9500 | S4: =(P4*Q4*R4*0.1) -> 49590
A5: 2026 | B5: 70 | C5: 0.71 | D5: 7500 | E5: =(B5*C5*D5*0.1) -> 37275 | H5: 2026 | I5: 77 | J5: 0.94 | K5: 9000 | L5: =(I5*J5*K5*0.1) -> 65142 | O5: 2026 | P5: 89 | Q5: 0.56 | R5: 9457 | S5: =(P5*Q5*R5*0.1) -> 47133.688
A6: 2027 | B6: 71 | C6: 0.7 | D6: 7433 | E6: =(B6*C6*D6*0.1) -> 36942.01 | H6: 2027 | I6: 76 | J6: 0.93 | K6: 8700 | L6: =(I6*J6*K6*0.1) -> 61491.6 | O6: 2027 | P6: 89 | Q6: 0.54 | R6: 9333 | S6: =(P6*Q6*R6*0.1) -> 44854.398
A7: 2028 | B7: 69 | C7: 0.69 | D7: 7412 | E7: =(B7*C7*D7*0.1) -> 35288.532 | H7: 2028 | I7: 75 | J7: 0.92 | K7: 8200 | L7: =(I7*J7*K7*0.1) -> 56580 | O7: 2028 | P7: 88 | Q7: 0.52 | R7: 9600 | S7: =(P7*Q7*R7*0.1) -> 43929.6
A8: 2029 | B8: 68 | C8: 0.68 | D8: 7311 | E8: =(B8*C8*D8*0.1) -> 33806.064 | H8: 2029 | I8: 74 | J8: 0.91 | K8: 7500 | L8: =(I8*J8*K8*0.1) -> 50505 | O8: 2029 | P8: 88 | Q8: 0.5 | R8: 9578 | S8: =(P8*Q8*R8*0.1) -> 42143.2
A9: 2030 | B9: 67 | C9: 0.67 | D9: 7456 | E9: =(B9*C9*D9*0.1) -> 33469.984 | H9: 2030 | I9: 73 | J9: 0.9 | K9: 7000 | L9: =(I9*J9*K9*0.1) -> 45990 | O9: 2030 | P9: 87 | Q9: 0.48 | R9: 9584 | S9: =(P9*Q9*R9*0.1) -> 40022.784
A10: 2031 | B10: 66 | C10: 0.66 | D10: 7550 | E10: =(B10*C10*D10*0.1) -> 32887.8 | H10: 2031 | I10: 72 | J10: 0.89 | K10: 6500 | L10: =(I10*J10*K10*0.1) -> 41652 | O10: 2031 | P10: 87 | Q10: 0.46 | R10: 9582 | S10: =(P10*Q10*R10*0.1) -> 38347.164
A12: OXIDE ORE BEST CASE PREDICTION | H12: MIXED ORE BEST CASE PREDICTION | O12: SULPHIDE ORE BEST CASE PREDICTION
A13: Year | B13: Copper recovery (%) | C13: Copper ore grade processed (%) | D13: Copper ore processed (000’s tonnes) | E13: Predicted Production | H13: Year | I13: Copper recovery (%) | J13: Copper ore grade processed (%) | K13: Copper ore processed (000’s tonnes) | L13: PREDICTED PRODUCTION | O13: Year | P13: Copper recovery (%) | Q13: Copper ore grade processed (%) | R13: Copper ore processed (000’s tonnes) | S13: Predicted production
A14: 2025 | B14: 73 | C14: 0.74 | D14: 7400 | E14: =(B14*C14*D14*0.1) -> 39974.8 | H14: 2025 | I14: 81 | J14: 1 | K14: 10000 | L14: =(I14*J14*K14*0.1) -> 81000 | O14: 2025 | P14: 91 | Q14: 0.62 | R14: 10000 | S14: =(P14*Q14*R14*0.1) -> 56420
A15: 2026 | B15: 72 | C15: 0.73 | D15: 7550 | E15: =(B15*C15*D15*0.1) -> 39682.8 | H15: 2026 | I15: 82 | J15: 1.01 | K15: 10500 | L15: =(I15*J15*K15*0.1) -> 86961 | O15: 2026 | P15: 90 | Q15: 0.64 | R15: 10400 | S15: =(P15*Q15*R15*0.1) -> 59904
A16: 2027 | B16: 73 | C16: 0.72 | D16: 7366 | E16: =(B16*C16*D16*0.1) -> 38715.696 | H16: 2027 | I16: 83 | J16: 1.09 | K16: 11000 | L16: =(I16*J16*K16*0.1) -> 99517 | O16: 2027 | P16: 90 | Q16: 0.66 | R16: 10800 | S16: =(P16*Q16*R16*0.1) -> 64152
A17: 2028 | B17: 73 | C17: 0.71 | D17: 7489 | E17: =(B17*C17*D17*0.1) -> 38815.487 | H17: 2028 | I17: 84 | J17: 1.1 | K17: 11500 | L17: =(I17*J17*K17*0.1) -> 106260 | O17: 2028 | P17: 91 | Q17: 0.68 | R17: 11200 | S17: =(P17*Q17*R17*0.1) -> 69305.6
A18: 2029 | B18: 71 | C18: 0.7 | D18: 7443 | E18: =(B18*C18*D18*0.1) -> 36991.71 | H18: 2029 | I18: 85 | J18: 1.1 | K18: 12000 | L18: =(I18*J18*K18*0.1) -> 112200 | O18: 2029 | P18: 91 | Q18: 0.7 | R18: 11500 | S18: =(P18*Q18*R18*0.1) -> 73255
A19: 2030 | B19: 70 | C19: 0.69 | D19: 7494 | E19: =(B19*C19*D19*0.1) -> 36196.02 | H19: 2030 | I19: 85 | J19: 1.1 | K19: 12100 | L19: =(I19*J19*K19*0.1) -> 113135 | O19: 2030 | P19: 91 | Q19: 0.72 | R19: 11800 | S19: =(P19*Q19*R19*0.1) -> 77313.6
A20: 2031 | B20: 73 | C20: 0.68 | D20: 7500 | E20: =(B20*C20*D20*0.1) -> 37230 | H20: 2031 | I20: 85 | J20: 1.1 | K20: 12150 | L20: =(I20*J20*K20*0.1) -> 113602.5 | O20: 2031 | P20: 91 | Q20: 0.74 | R20: 12000 | S20: =(P20*Q20*R20*0.1) -> 80808
A22: OXIDE ORE OPTIMISTIC PREDICTION | H22: MIXED ORE OPTIMISTIC PREDICTION | O22: SULPHIDE ORE OPTIMISTIC PREDICTION
A23: Year | B23: Copper recovery (%) | C23: Copper ore grade processed (%) | D23: Copper ore processed (000’s tonnes) | E23: Predicted Production | H23: Year | I23: Copper recovery (%) | J23: Copper ore grade processed (%) | K23: Copper ore processed (000’s tonnes) | L23: Predicted production | O23: Year | P23: Copper recovery (%) | Q23: Copper ore grade processed (%) | R23: Copper ore processed (000’s tonnes) | S23: Predicted Production
A24: 2025 | B24: 75 | C24: 0.76 | D24: 7600 | E24: =(B24*C24*D24*0.1) -> 43320 | H24: 2025 | I24: 84 | J24: 1.05 | K24: 11000 | L24: =(I24*J24*K24*0.1) -> 97020 | O24: 2025 | P24: 92 | Q24: 0.7 | R24: 11000 | S24: =(P24*Q24*R24*0.1) -> 70840
A25: 2026 | B25: 76 | C25: 0.77 | D25: 7540 | E25: =(B25*C25*D25*0.1) -> 44124.08 | H25: 2026 | I25: 85 | J25: 1.1 | K25: 11500 | L25: =(I25*J25*K25*0.1) -> 107525 | O25: 2026 | P25: 92 | Q25: 0.75 | R25: 11479 | S25: =(P25*Q25*R25*0.1) -> 79205.1
A26: 2027 | B26: 77 | C26: 0.78 | D26: 7590 | E26: =(B26*C26*D26*0.1) -> 45585.54 | H26: 2027 | I26: 86 | J26: 1.15 | K26: 12000 | L26: =(I26*J26*K26*0.1) -> 118680 | O26: 2027 | P26: 92 | Q26: 0.8 | R26: 12100 | S26: =(P26*Q26*R26*0.1) -> 89056
A27: 2028 | B27: 78 | C27: 0.79 | D27: 7444 | E27: =(B27*C27*D27*0.1) -> 45869.928 | H27: 2028 | I27: 87 | J27: 1.2 | K27: 12500 | L27: =(I27*J27*K27*0.1) -> 130500 | O27: 2028 | P27: 93 | Q27: 0.85 | R27: 12690 | S27: =(P27*Q27*R27*0.1) -> 100314.45
A28: 2029 | B28: 79 | C28: 0.8 | D28: 7469 | E28: =(B28*C28*D28*0.1) -> 47204.08 | H28: 2029 | I28: 89 | J28: 1.25 | K28: 13000 | L28: =(I28*J28*K28*0.1) -> 144625 | O28: 2029 | P28: 93 | Q28: 0.9 | R28: 13200 | S28: =(P28*Q28*R28*0.1) -> 110484
A29: 2030 | B29: 80 | C29: 0.82 | D29: 7509 | E29: =(B29*C29*D29*0.1) -> 49259.04 | H29: 2030 | I29: 90 | J29: 1.3 | K29: 14000 | L29: =(I29*J29*K29*0.1) -> 163800 | O29: 2030 | P29: 93 | Q29: 0.91 | R29: 13900 | S29: =(P29*Q29*R29*0.1) -> 117635.7
A30: 2031 | B30: 81 | C30: 0.83 | D30: 7512 | E30: =(B30*C30*D30*0.1) -> 50503.176 | H30: 2031 | I30: 91 | J30: 1.35 | K30: 15000 | L30: =(I30*J30*K30*0.1) -> 184275 | O30: 2031 | P30: 93 | Q30: 0.92 | R30: 14000 | S30: =(P30*Q30*R30*0.1) -> 119784
A32: TOTAL KANSANSHI PRODUCTION PESSIMISTIC PREDICTION
A33: Year | B33: Oxide ore predicted copper production | C33: Mixed Ore predicted copper production | D33: Sulphide ore predicted copper production | E33: Kansanshi total predited copper production
A34: 2025 | B34: 37843 | C34: 70395 | D34: 49590 | E34: =(B34+C34+D34) -> 157828
A35: 2026 | B35: 37275 | C35: 65142 | D35: 47134 | E35: =(B35+C35+D35) -> 149551
A36: 2027 | B36: 36942 | C36: 61492 | D36: 44854 | E36: =(B36+C36+D36) -> 143288
A37: 2028 | B37: 35289 | C37: 56580 | D37: 43930 | E37: =(B37+C37+D37) -> 135799
A38: 2029 | B38: 33806 | C38: 50505 | D38: 42143 | E38: =(B38+C38+D38) -> 126454
A39: 2030 | B39: 33470 | C39: 45990 | D39: 40023 | E39: =(B39+C39+D39) -> 119483
A40: 2031 | B40: 32888 | C40: 41652 | D40: 38347 | E40: =(B40+C40+D40) -> 112887
A42: TOTAL KANSANSHI PREDICTION BEST CASE SCENARIO
A43: Year | B43: Oxide ore predicted copper production | C43: Mixed Ore predicted copper production | D43: Sulphide ore predicted copper production | E43: Kansanshi total predited copper production
A44: 2025 | B44: 39975 | C44: 81000 | D44: 56420 | E44: =SUM(B44:D44) -> 177395
A45: 2026 | B45: 39683 | C45: 86961 | D45: 59904 | E45: =SUM(B45:D45) -> 186548
...

Sheet Sentinel regression stats
A1: SUMMARY OUTPUT
A3: Regression Statistics
A4: Multiple R | B4: 0.99626217
A5: R Square | B5: 0.99253831
A6: Adjusted R Square | B6: 0.98880746
A7: Standard Error | B7: 6980.7368
A8: Observations | B8: 10
A10: ANOVA
B11: df | C11: SS | D11: MS | E11: F | F11: Significance F
A12: Regression | B12: 3 | C12: 3.8892303e+10 | D12: 1.2964101e+10 | E12: 266.03567 | F12: 9.0623641e-07
A13: Residual | B13: 6 | C13: 2.9238412e+08 | D13: 48730686
A14: Total | B14: 9 | C14: 3.9184687e+10
B16: Coefficients | C16: Standard Error | D16: t Stat | E16: P-value | F16: Lower 95% | G16: Upper 95% | H16: Lower 95.0% | I16: Upper 95.0%
A17: Intercept | B17: -113731.27 | C17: 75490.727 | D17: -1.5065595 | E17: 0.18264044 | F17: -298450.42 | G17: 70987.884 | H17: -298450.42 | I17: 70987.884
A18: Copper recovery (%) | B18: 1763.3439 | C18: 435.20993 | D18: 4.0517088 | E18: 0.0067131373 | F18: 698.42357 | G18: 2828.2642 | H18: 698.42357 | I18: 2828.2642
A19: Copper ore grade processed (%) | B19: 47408.884 | C19: 105785.45 | D19: 0.44816072 | E19: 0.6697659 | F19: -211438.79 | G19: 306256.56 | H19: -211438.79 | I19: 306256.56
A20: Copper ore processed (000’s tonnes) | B20: 3.0685336 | C20: 0.54183902 | D20: 5.6631832 | E20: 0.0013031791 | F20: 1.7427013 | G20: 4.394366 | H20: 1.7427013 | I20: 4.394366
A24: RESIDUAL OUTPUT
A26: Observation | B26: Predicted Copper production (tonnes) | C26: Residuals
A27: 1 | B27: 30019.727 | C27: 2951.2727
A28: 2 | B28: 146220.94 | C28: -6620.9448
A29: 3 | B29: 192529.47 | C29: -1846.4659
A30: 4 | B30: 220028.48 | C30: 3627.5189
A31: 5 | B31: 220359.88 | C31: -353.88269
A32: 6 | B32: 241845.28 | C32: 9370.7165
A33: 7 | B33: 238335.94 | C33: -5647.9431
A34: 8 | B34: 246495.65 | C34: -4044.645
A35: 9 | B35: 219236.33 | C35: -5190.3277
A36: 10 | B36: 223037.3 | C36: 7754.701

Sheet Sentinel regression data
A1: YEAR | B1: Copper production (tonnes) | C1: Copper recovery (%) | D1: Copper ore grade processed (%) | E1: Copper ore processed (000’s tonnes)
A2: 2015 | B2: 32971 | C2: 41 | D2: 0.6 | E2: 14016
A3: 2016 | B3: 139600 | C3: 68 | D3: 0.6 | E3: 36369
A4: 2017 | B4: 190683 | C4: 87 | D4: 0.5 | E4: 42087
A5: 2018 | B5: 223656 | C5: 91 | D5: 0.5 | E5: 48750
A6: 2019 | B6: 220006 | C6: 91 | D6: 0.5 | E6: 48858
A7: 2020 | B7: 251216 | C7: 90 | D7: 0.49 | E7: 56589
A8: 2021 | B8: 232688 | C8: 89 | D8: 0.47 | E8: 56329
A9: 2022 | B9: 242451 | C9: 90 | D9: 0.46 | E9: 58568
A10: 2023 | B10: 214046 | C10: 90 | D10: 0.49 | E10: 49221
A11: 2024 | B11: 230792 | C11: 88 | D11: 0.51 | E11: 51300

Sheet Kansanshi Regression Stats
A1: SUMMARY OUTPUT | M1: SUMMARY OUTPUT | AA1: SUMMARY OUTPUT
A3: Regression Statistics | M3: Regression Statistics | AA3: Regression Statistics
A4: Multiple R | B4: 0.84297818 | M4: Multiple R | N4: 0.92138949 | AA4: Multiple R | AB4: 0.8513976
A5: R Square | B5: 0.71061221 | M5: R Square | N5: 0.84895859 | AA5: R Square | AB5: 0.72487788
A6: Adjusted R Square | B6: 0.56591831 | M6: Adjusted R Square | N6: 0.77343789 | AA6: Adjusted R Square | AB6: 0.58731682
A7: Standard Error | B7: 29015.425 | M7: Standard Error | N7: 20962.199 | AA7: Standard Error | AB7: 28291.215
A8: Observations | B8: 10 | M8: Observations | N8: 10 | AA8: Observations | AB8: 10
A10: ANOVA | M10: ANOVA | AA10: ANOVA
B11: df | C11: SS | D11: MS | E11: F | F11: Significance F | N11: df | O11: SS | P11: MS | Q11: F | R11: Significance F | AB11: df | AC11: SS | AD11: MS | AE11: F | AF11: Significance F
A12: Regression | B12: 3 | C12: 1.2403995e+10 | D12: 4.134665e+09 | E12: 4.9111416 | F12: 0.046879973 | M12: Regression | N12: 3 | O12: 1.4818882e+10 | P12: 4.9396272e+09 | Q12: 11.241402 | R12: 0.0070969349 | AA12: Regression | AB12: 3 | AC12: 1.2653008e+10 | AD12: 4.2176692e+09 | AE12: 5.269499 | AF12: 0.040560454
A13: Residual | B13: 6 | C13: 5.0513694e+09 | D13: 8.418949e+08 | M13: Residual | N13: 6 | O13: 2.6364828e+09 | P13: 4.394138e+08 | AA13: Residual | AB13: 6 | AC13: 4.8023569e+09 | AD13: 8.0039282e+08
A14: Total | B14: 9 | C14: 1.7455364e+10 | M14: Total | N14: 9 | O14: 1.7455364e+10 | AA14: Total | AB14: 9 | AC14: 1.7455364e+10
B16: Coefficients | C16: Standard Error | D16: t Stat | E16: P-value | F16: Lower 95% | G16: Upper 95% | H16: Lower 95.0% | I16: Upper 95.0% | N16: Coefficients | O16: Standard Error | P16: t Stat | Q16: P-value | R16: Lower 95% | S16: Upper 95% | T16: Lower 95.0% | U16: Upper 95.0% | AB16: Coefficients | AC16: Standard Error | AD16: t Stat | AE16: P-value | AF16: Lower 95% | AG16: Upper 95% | AH16: Lower 95.0% | AI16: Upper 95.0%
A17: Intercept | B17: 7814.5005 | C17: 457796.43 | D17: 0.017069816 | E17: 0.98693438 | F17: -1112373 | G17: 1128002 | H17: -1112373 | I17: 1128002 | M17: Intercept | N17: 58678.588 | O17: 165758.45 | P17: 0.35400058 | Q17: 0.73544641 | R17: -346917.73 | S17: 464274.91 | T17: -346917.73 | U17: 464274.91 | AA17: Intercept | AB17: -1748251.3 | AC17: 1019972.8 | AD17: -1.7140177 | AE17: 0.13735491 | AF17: -4244034.8 | AG17: 747532.08 | AH17: -4244034.8 | AI17: 747532.08
A18: Oxide copper recovery(%) | B18: 913.4471 | C18: 2501.7611 | D18: 0.36512164 | E18: 0.72754573 | F18: -5208.1417 | G18: 7035.0359 | H18: -5208.1417 | I18: 7035.0359 | M18: Mixed copper recovery(%) | N18: 337.80515 | O18: 1990.8152 | P18: 0.16968182 | Q18: 0.87083689 | R18: -4533.5442 | S18: 5209.1545 | T18: -4533.5442 | U18: 5209.1545 | AA18: Sulphide copper recovery(%) | AB18: 20520.199 | AC18: 11672.629 | AD18: 1.7579757 | AE18: 0.12925668 | AF18: -8041.6958 | AG18: 49082.094 | AH18: -8041.6958 | AI18: 49082.094
A19: Oxide ore grade processed(%) | B19: 82298.816 | C19: 79098.236 | D19: 1.0404633 | E19: 0.33822336 | F19: -111247.6 | G19: 275845.23 | H19: -111247.6 | I19: 275845.23 | M19: Mixed ore grade processed(%) | N19: 254578.08 | O19: 62860.954 | P19: 4.0498602 | Q19: 0.0067271923 | R19: 100762.86 | S19: 408393.29 | T19: 100762.86 | U19: 408393.29 | AA19: Sulphide ore grade processed(%) | AB19: 120902.14 | AC19: 125058.96 | AD19: 0.96676114 | AE19: 0.37099894 | AF19: -185106.11 | AG19: 426910.4 | AH19: -185106.11 | AI19: 426910.4
A20: Oxide ore tonnes milled(000's) | B20: 5.5198671 | C20: 57.500137 | D20: 0.095997461 | E20: 0.92664865 | F20: -135.1779 | G20: 146.21763 | H20: -135.1779 | I20: 146.21763 | M20: Mixed ore tonnes milled(000's) | N20: -13.777784 | O20: 8.2242085 | P20: -1.6752717 | Q20: 0.14490023 | R20: -33.901697 | S20: 6.3461294 | T20: -33.901697 | U20: 6.3461294 | AA20: Sulphide ore tonnes milled(000's) | AB20: 0.34705668 | AC20: 6.0604572 | AD20: 0.057265759 | AE20: 0.95619297 | AF20: -14.482348 | AG20: 15.176461 | AH20: -14.482348 | AI20: 15.176461
A24: RESIDUAL OUTPUT | M24: RESIDUAL OUTPUT | AA24: RESIDUAL OUTPUT
A26: Observation | B26: Predicted Copper production (tonnes) | C26: Residuals | M26: Observation | N26: Predicted Copper production (tonnes) | O26: Residuals | AA26: Observation | AB26: Predicted Copper production (tonnes) | AC26: Residuals
A27: 1 | B27: 241845.99 | C27: -15171.99 | M27: 1 | N27: 212183.49 | O27: 14490.513 | AA27: 1 | AB27: 218687.69 | AC27: 7986.3104
A28: 2 | B28: 256185.33 | C28: -2913.3318 | M28: 2 | N28: 232057.58 | O28: 21214.418 | AA28: 2 | AB28: 240489.22 | AC28: 12782.778
A29: 3 | B29: 248908.02 | C29: 1892.9767 | M29: 3 | N29: 231789.16 | O29: 19011.835 | AA29: 3 | AB29: 220309.83 | AC29: 30491.167
A30: 4 | B30: 245796.99 | C30: 5725.0114 | M30: 4 | N30: 243446.43 | O30: 8075.567 | AA30: 4 | AB30: 217894.57 | AC30: 33627.434
A31: 5 | B31: 214640.4 | C31: 17602.6 | M31: 5 | N31: 245921.41 | O31: -13678.407 | AA31: 5 | AB31: 231169.51 | AC31: 1073.4919
A32: 6 | B32: 194842.19 | C32: 26644.81 | M32: 6 | N32: 228095.72 | O32: -6608.7211 | AA32: 6 | AB32: 244650.41 | AC32: -23163.407
A33: 7 | B33: 169641.83 | C33: 32517.174 | M33: 7 | N33: 226048.63 | O33: -23889.629 | AA33: 7 | AB33: 230126.38 | AC33: -27967.38
A34: 8 | B34: 156604.71 | C34: -10322.715 | M34: 8 | N34: 137792.31 | O34: 8489.6896 | AA34: 8 | AB34: 168454.18 | AC34: -22172.182
A35: 9 | B35: 185464.18 | C35: -50637.176 | M35: 9 | N35: 135952.23 | O35: -1125.2279 | AA35: 9 | AB35: 123505.76 | AC35: 11321.245
A36: 10 | B36: 176266.36 | C36: -5337.3589 | M36: 10 | N36: 196909.04 | O36: -25980.037 | AA36: 10 | AB36: 194908.46 | AC36: -23979.458

Sheet Kansanshi regression data
A1: YEAR | B1: Copper production (tonnes) | C1: Oxide copper recovery(%) | D1: Oxide ore grade processed(%) | E1: Oxide ore tonnes milled(000's) | F1: Mixed copper recovery(%) | G1: Mixed ore grade processed(%) | H1: Mixed ore tonnes milled(000's) | I1: Sulphide copper recovery(%) | J1: Sulphide ore grade processed(%) | K1: Sulphide ore tonnes milled(000's)
A2: 2015 | B2: 226674 | C2: 80 | D2: 1.5 | E2: 6795 | F2: 72 | G2: 1.1 | H2: 10949 | I2: 91 | J2: 0.8 | K2: 8296
A3: 2016 | B3: 253272 | C3: 94 | D3: 1.5 | E3: 7076 | F3: 84 | G3: 1 | H3: 7953 | I3: 92 | J3: 0.8 | K3: 11988
A4: 2017 | B4: 250801 | C4: 87 | D4: 1.5 | E4: 6916 | F4: 85 | G4: 1 | H4: 7997 | I4: 91 | J4: 0.8 | K4: 12970
A5: 2018 | B5: 251522 | C5: 89 | D5: 1.44 | E5: 6916 | F5: 82 | G5: 1.06 | H5: 8186 | I5: 91 | J5: 0.78 | K5: 12978
A6: 2019 | B6: 232243 | C6: 82 | D6: 1.12 | E6: 7201 | F6: 77 | G6: 1.05 | H6: 7699 | I6: 91 | J6: 0.89 | K6: 12908
A7: 2020 | B7: 221487 | C7: 76 | D7: 0.93 | E7: 7440 | F7: 81 | G7: 1 | H7: 8167 | I7: 92 | J7: 0.83 | K7: 13527
A8: 2021 | B8: 202159 | C8: 69 | D8: 0.72 | E8: 7164 | F8: 82 | G8: 0.96 | H8: 7601 | I8: 91 | J8: 0.88 | K8: 13386
A9: 2022 | B9: 146282 | C9: 64 | D9: 0.57 | E9: 7866 | F9: 74 | G9: 0.63 | H9: 7713 | I9: 89 | J9: 0.71 | K9: 13160
A10: 2023 | B10: 134827 | C10: 76 | D10: 0.83 | E10: 7232 | F10: 71 | G10: 0.63 | H10: 7773 | I10: 88 | J10: 0.51 | K10: 12446
A11: 2024 | B11: 170929 | C11: 73 | D11: 0.74 | E11: 7404 | F11: 81 | G11: 0.98 | H11: 10061 | I11: 91 | J11: 0.6 | K11: 9452

Sheet Copper producton Sentinel
A1: YEAR | B1: Copper production (tonnes) | C1: Copper production (tonnes) | E1: Z score for Copper production | F1: Year on year growth rate | G1: Moving averages for 3 years | H1: Moving averages 5 years
A2: 2015 | B2: 32971 | E2: =(B2-D3)/D7 -> -2.4981897
A3: 2016 | B3: 139600 | C3: Mean | D3: 197810.9 | E3: =(B3-D3)/D7 -> -0.88220066 | F3: =(B3-B2)/B2 -> 3.2340238
A4: 2017 | B4: 190683 | C4: Standard Error | D4: 20865.891 | E4: =(B4-D3)/D7 -> -0.1080251 | F4: =(B4-B3)/B3 -> 0.36592407 | G4: =(B2+B3+B4)/3 -> 121084.67
A5: 2018 | B5: 223656 | C5: Median | D5: 221831 | E5: =(B5-D3)/D7 -> 0.39168892 | F5: =(B5-B4)/B4 -> 0.1729205 | G5: =(B3+B4+B5)/3 -> 184646.33
A6: 2019 | B6: 220006 | C6: Mode | D6: #N/A | E6: =(B6-D3)/D7 -> 0.33637226 | F6: =(B6-B5)/B5 -> -0.016319705 | G6: =(B4+B5+B6)/3 -> 211448.33 | H6: =(B2+B3+B4+B5+B6)/5 -> 161383.2
A7: 2020 | B7: 251216 | C7: Standard Deviation | D7: 65983.741 | E7: =(B7-D3)/D7 -> 0.80936757 | F7: =(B7-B6)/B6 -> 0.14185977 | G7: =(B5+B6+B7)/3 -> 231626 | H7: =(B3+B4+B5+B6+B7)/5 -> 205032.2
A8: 2021 | B8: 232688 | C8: Sample Variance | D8: 4.3538541e+09 | E8: =(B8-D3)/D7 -> 0.52857112 | F8: =(B8-B7)/B7 -> -0.073753264 | G8: =(B6+B7+B8)/3 -> 234636.67 | H8: =(B4+B5+B6+B7+B8)/5 -> 223649.8
A9: 2022 | B9: 242451 | C9: Kurtosis | D9: 4.4725915 | E9: =(B9-D3)/D7 -> 0.67653181 | F9: =(B9-B8)/B8 -> 0.041957471 | G9: =(B7+B8+B9)/3 -> 242118.33 | H9: =(B5+B6+B7+B8+B9)/5 -> 234003.4
A10: 2023 | B10: 214046 | C10: Skewness | D10: -2.0907631 | E10: =(B10-D3)/D7 -> 0.24604698 | F10: =(B10-B9)/B9 -> -0.11715769 | G10: =(B8+B9+B10)/3 -> 229728.33 | H10: =(B6+B7+B8+B9+B10)/5 -> 232081.4
A11: 2024 | B11: 230792 | C11: Range | D11: 218245 | E11: =(B11-D3)/D7 -> 0.49983677 | F11: =(B11-B10)/B10 -> 0.078235519 | G11: =(B9+B10+B11)/3 -> 229096.33 | H11: =(B7+B8+B9+B10+B11)/5 -> 234238.6
C12: Minimum | D12: 32971
C13: Maximum | D13: 251216
C14: Sum | D14: 1978109
C15: Count | D15: 10

Sheet Sentinel copper recovery%
A1: YEAR | B1: Copper recovery (%) | C1: Copper recovery (%) | E1: Z SCORE FOR COPPER RECOVERY(%) | F1: Year on Year growth rate | G1: Moving averages for 3 years | H1: Moving averages for 5 years
A2: 2015 | B2: 41 | E2: =(B2-D3)/D7 -> -2.5745461
A3: 2016 | B3: 68 | C3: Mean | D3: 82.5 | E3: =(B3-D3)/D7 -> -0.89954019 | F3: =(B3-B2)/B2 -> 0.65853659
A4: 2017 | B4: 87 | C4: Standard Error | D4: 5.097385 | E4: =(B4-D3)/D7 -> 0.27916764 | F4: =(B4-B3)/B3 -> 0.27941176 | G4: =(B2+B3+B4)/3 -> 65.333333
A5: 2018 | B5: 91 | C5: Median | D5: 89.5 | E5: =(B5-D3)/D7 -> 0.52731666 | F5: =(B5-B4)/B4 -> 0.045977011 | G5: =(B3+B4+B5)/3 -> 82
A6: 2019 | B6: 91 | C6: Mode | D6: 90 | E6: =(B6-D3)/D7 -> 0.52731666 | F6: =(B6-B5)/B5 -> 0 | G6: =(B4+B5+B6)/3 -> 89.666667 | H6: =(B2+B3+B4+B5+B6)/5 -> 75.6
A7: 2020 | B7: 90 | C7: Standard Deviation | D7: 16.119347 | E7: =(B7-D3)/D7 -> 0.46527941 | F7: =(B7-B6)/B6 -> -0.010989011 | G7: =(B5+B6+B7)/3 -> 90.666667 | H7: =(B3+B4+B5+B6+B7)/5 -> 85.4
A8: 2021 | B8: 89 | C8: Sample Variance | D8: 259.83333 | E8: =(B8-D3)/D7 -> 0.40324215 | F8: =(B8-B7)/B7 -> -0.011111111 | G8: =(B6+B7+B8)/3 -> 90 | H8: =(B4+B5+B6+B7+B8)/5 -> 89.6
A9: 2022 | B9: 90 | C9: Kurtosis | D9: 5.466921 | E9: =(B9-D3)/D7 -> 0.46527941 | F9: =(B9-B8)/B8 -> 0.011235955 | G9: =(B7+B8+B9)/3 -> 89.666667 | H9: =(B5+B6+B7+B8+B9)/5 -> 90.2
A10: 2023 | B10: 90 | C10: Skewness | D10: -2.3708657 | E10: =(B10-D3)/D7 -> 0.46527941 | F10: =(B10-B9)/B9 -> 0 | G10: =(B8+B9+B10)/3 -> 89.666667 | H10: =(B6+B7+B8+B9+B10)/5 -> 90
A11: 2024 | B11: 88 | C11: Range | D11: 50 | E11: =(B11-D3)/D7 -> 0.3412049 | F11: =(B11-B10)/B10 -> -0.022222222 | G11: =(B9+B10+B11)/3 -> 89.333333 | H11: =(B7+B8+B9+B10+B11)/5 -> 89.4
C12: Minimum | D12: 41
C13: Maximum | D13: 91
C14: Sum | D14: 825
C15: Count | D15: 10

Sheet Sentinel Copper ore grade
A1: YEAR | B1: Copper ore grade processed (%) | C1: Zscore for ore grade processed(%) | D1: Copper ore grade processed (%) | F1: Year on year growth rates | G1: Moving averages 3 years | H1: Moving averages 5 years
A2: 2015 | B2: 0.6 | C2: =(B2-E3)/E7 -> 1.8063558
A3: 2016 | B3: 0.6 | C3: =(B3-E3)/E7 -> 1.8063558 | D3: Mean | E3: 0.512 | F3: =(B3-B2)/B2 -> 0
A4: 2017 | B4: 0.5 | C4: =(B4-E3)/E7 -> -0.24632125 | D4: Standard Error | E4: 0.015405627 | F4: =(B4-B3)/B3 -> -0.16666667 | G4: =(B2+B3+B4)/3 -> 0.56666667
A5: 2018 | B5: 0.5 | C5: =(B5-E3)/E7 -> -0.24632125 | D5: Median | E5: 0.5 | F5: =(B5-B4)/B4 -> 0 | G5: =(B3+B4+B5)/3 -> 0.53333333
A6: 2019 | B6: 0.5 | C6: =(B6-E3)/E7 -> -0.24632125 | D6: Mode | E6: 0.5 | F6: =(B6-B5)/B5 -> 0 | G6: =(B4+B5+B6)/3 -> 0.5 | H6: =(B2+B3+B4+B5+B6)/5 -> 0.54
A7: 2020 | B7: 0.49 | C7: =(B7-E3)/E7 -> -0.45158895 | D7: Standard Deviation | E7: 0.048716869 | F7: =(B7-B6)/B6 -> -0.02 | G7: =(B5+B6+B7)/3 -> 0.49666667 | H7: =(B3+B4+B5+B6+B7)/5 -> 0.518
A8: 2021 | B8: 0.47 | C8: =(B8-E3)/E7 -> -0.86212437 | D8: Sample Variance | E8: 0.0023733333 | F8: =(B8-B7)/B7 -> -0.040816327 | G8: =(B6+B7+B8)/3 -> 0.48666667 | H8: =(B4+B5+B6+B7+B8)/5 -> 0.492
A9: 2022 | B9: 0.46 | C9: =(B9-E3)/E7 -> -1.0673921 | D9: Kurtosis | E9: 0.73250694 | F9: =(B9-B8)/B8 -> -0.021276596 | G9: =(B7+B8+B9)/3 -> 0.47333333 | H9: =(B5+B6+B7+B8+B9)/5 -> 0.484
A10: 2023 | B10: 0.49 | C10: =(B10-E3)/E7 -> -0.45158895 | D10: Skewness | E10: 1.3475018 | F10: =(B10-B9)/B9 -> 0.065217391 | G10: =(B8+B9+B10)/3 -> 0.47333333 | H10: =(B6+B7+B8+B9+B10)/5 -> 0.482
A11: 2024 | B11: 0.51 | C11: =(B11-E3)/E7 -> -0.041053541 | D11: Range | E11: 0.14 | F11: =(B11-B10)/B10 -> 0.040816327 | G11: =(B9+B10+B11)/3 -> 0.48666667 | H11: =(B7+B8+B9+B10+B11)/5 -> 0.484
D12: Minimum | E12: 0.46
D13: Maximum | E13: 0.6
D14: Sum | E14: 5.12
D15: Count | E15: 10

Sheet Copper ore processed sentinel
A1: YEAR | B1: Copper ore processed (000’s tonnes) | C1: Year on year growth rates | D1: Zscore for copper production(000's tonnes) | E1: Copper ore processed (000’s tonnes) | G1: Moving averages 3 years | H1: Moving averages 5 years
A2: 2015 | B2: 14016 | D2: =(B2-F3)/F7 -> -2.4404054
A3: 2016 | B3: 36369 | C3: =(B3-B2)/B2 -> 1.5948202 | D3: =(B3-F3)/F7 -> -0.74748762 | E3: Mean | F3: 46238.7
A4: 2017 | B4: 42087 | C4: =(B4-B3)/B3 -> 0.15722181 | D4: =(B4-F3)/F7 -> -0.31443148 | E4: Standard Error | F4: 4175.4179 | G4: =(B2+B3+B4)/3 -> 30824
A5: 2018 | B5: 48750 | C5: =(B5-B4)/B4 -> 0.15831492 | D5: =(B5-F3)/F7 -> 0.1901948 | E5: Median | F5: 49039.5 | G5: =(B3+B4+B5)/3 -> 42402
A6: 2019 | B6: 48858 | C6: =(B6-B5)/B5 -> 0.0022153846 | D6: =(B6-F3)/F7 -> 0.19837425 | E6: Mode | F6: #N/A | G6: =(B4+B5+B6)/3 -> 46565 | H6: =(B2+B3+B4+B5+B6)/5 -> 38016
A7: 2020 | B7: 56589 | C7: =(B7-B6)/B6 -> 0.15823407 | D7: =(B7-F3)/F7 -> 0.78388615 | E7: Standard Deviation | F7: 13203.831 | G7: =(B5+B6+B7)/3 -> 51399 | H7: =(B3+B4+B5+B6+B7)/5 -> 46530.6
A8: 2021 | B8: 56329 | C8: =(B8-B7)/B7 -> -0.0045945325 | D8: =(B8-F3)/F7 -> 0.7641949 | E8: Sample Variance | F8: 1.7434114e+08 | G8: =(B6+B7+B8)/3 -> 53925.333 | H8: =(B4+B5+B6+B7+B8)/5 -> 50522.6
A9: 2022 | B9: 58568 | C9: =(B9-B8)/B8 -> 0.03974862 | D9: =(B9-F3)/F7 -> 0.9337669 | E9: Kurtosis | F9: 3.8176387 | G9: =(B7+B8+B9)/3 -> 57162 | H9: =(B5+B6+B7+B8+B9)/5 -> 53818.8
A10: 2023 | B10: 49221 | C10: =(B10-B9)/B9 -> -0.15959227 | D10: =(B10-F3)/F7 -> 0.22586627 | E10: Skewness | F10: -1.8190562 | G10: =(B8+B9+B10)/3 -> 54706 | H10: =(B6+B7+B8+B9+B10)/5 -> 53913
A11: 2024 | B11: 51300 | C11: =(B11-B10)/B10 -> 0.042238069 | D11: =(B11-F3)/F7 -> 0.38332058 | E11: Range | F11: 44852
E12: Minimum | F12: 14016
E13: Maximum | F13: 58868
E14: Sum | F14: 462387
E15: Count | F15: 10

Sheet Copper production Kansanshi
A1: YEAR | B1: Copper production (tonnes) | C1: Year on year growth rate | D1: Copper production (tonnes) | F1: Z score for Copper production (tonnes) | G1: Moving averages for 3 years | H1: Moving averages for 5 years
A2: 2015 | B2: 226674 | F2: =(B2-E3)/E7 -> 0.40087572
A3: 2016 | B3: 253272 | C3: =(B3-B2)/B2 -> 0.11734032 | D3: Mean | E3: 209019.6 | F3: =(B3-E3)/E7 -> 1.0048324
A4: 2017 | B4: 250801 | C4: =(B4-B3)/B3 -> -0.0097563094 | D4: Standard Error | E4: 13926.539 | F4: =(B4-E3)/E7 -> 0.94872377 | G4: =(B2+B3+B4)/3 -> 243582.33
A5: 2018 | B5: 251522 | C5: =(B5-B4)/B4 -> 0.0028747892 | D5: Median | E5: 224080.5 | F5: =(B5-E3)/E7 -> 0.96509541 | G5: =(B3+B4+B5)/3 -> 251865
A6: 2019 | B6: 232243 | C6: =(B6-B5)/B5 -> -0.076649359 | D6: Mode | E6: #N/A | F6: =(B6-E3)/E7 -> 0.52733014 | G6: =(B4+B5+B6)/3 -> 244855.33 | H6: =(B2+B3+B4+B5+B6)/5 -> 242902.4
A7: 2020 | B7: 221487 | C7: =(B7-B6)/B6 -> -0.04631356 | D7: Standard Deviation | E7: 44039.584 | F7: =(B7-E3)/E7 -> 0.28309532 | G7: =(B5+B6+B7)/3 -> 235084 | H7: =(B3+B4+B5+B6+B7)/5 -> 241865
A8: 2021 | B8: 202159 | C8: =(B8-B7)/B7 -> -0.087264715 | D8: Sample Variance | E8: 1.9394849e+09 | F8: =(B8-E3)/E7 -> -0.15578258 | G8: =(B6+B7+B8)/3 -> 218629.67 | H8: =(B4+B5+B6+B7+B8)/5 -> 231642.4
A9: 2022 | B9: 146282 | C9: =(B9-B8)/B8 -> -0.27640125 | D9: Kurtosis | E9: -0.94751146 | F9: =(B9-E3)/E7 -> -1.424573 | G9: =(B7+B8+B9)/3 -> 189976 | H9: =(B5+B6+B7+B8+B9)/5 -> 210738.6
A10: 2023 | B10: 134827 | C10: =(B10-B9)/B9 -> -0.078307652 | D10: Skewness | E10: -0.73917769 | F10: =(B10-E3)/E7 -> -1.6846799 | G10: =(B8+B9+B10)/3 -> 161089.33 | H10: =(B6+B7+B8+B9+B10)/5 -> 187399.6
A11: 2024 | B11: 170929 | C11: =(B11-B10)/B10 -> 0.26776536 | D11: Range | E11: 118445 | F11: =(B11-E3)/E7 -> -0.86491735 | G11: =(B9+B10+B11)/3 -> 150679.33 | H11: =(B7+B8+B9+B10+B11)/5 -> 175136.8
D12: Minimum | E12: 134827
D13: Maximum | E13: 253272
D14: Sum | E14: 2090196
D15: Count | E15: 10

Sheet Oxide copper recovery(%)
A1: YEAR | B1: Oxide copper recovery(%) | C1: Year on year growth rate | D1: Oxide copper recovery(%) | F1: Z score for Oxide copper recovery(%) | G1: Moving averages for 3 years | H1: Moving averages for 5 years
A2: 2015 | B2: 80 | F2: =(B2-E3)/E7 -> 0.10755521
A3: 2016 | B3: 94 | C3: =(B3-B2)/B2 -> 0.175 | D3: Mean | E3: 79 | F3: =(B3-E3)/E7 -> 1.6133282
A4: 2017 | B4: 87 | C4: =(B4-B3)/B3 -> -0.074468085 | D4: Standard Error | E4: 2.9401436 | F4: =(B4-E3)/E7 -> 0.86044169 | G4: =(B2+B3+B4)/3 -> 87
A5: 2018 | B5: 89 | C5: =(B5-B4)/B4 -> 0.022988506 | D5: Median | E5: 78 | F5: =(B5-E3)/E7 -> 1.0755521 | G5: =(B3+B4+B5)/3 -> 90
A6: 2019 | B6: 82 | C6: =(B6-B5)/B5 -> -0.078651685 | D6: Mode | E6: 76 | F6: =(B6-E3)/E7 -> 0.32266563 | G6: =(B4+B5+B6)/3 -> 86 | H6: =(B2+B3+B4+B5+B6)/5 -> 86.4
A7: 2020 | B7: 76 | C7: =(B7-B6)/B6 -> -0.073170732 | D7: Standard Deviation | E7: 9.2975505 | F7: =(B7-E3)/E7 -> -0.32266563 | G7: =(B5+B6+B7)/3 -> 82.333333 | H7: =(B3+B4+B5+B6+B7)/5 -> 85.6
A8: 2021 | B8: 69 | C8: =(B8-B7)/B7 -> -0.092105263 | D8: Sample Variance | E8: 86.444444 | F8: =(B8-E3)/E7 -> -1.0755521 | G8: =(B6+B7+B8)/3 -> 75.666667 | H8: =(B4+B5+B6+B7+B8)/5 -> 80.6
A9: 2022 | B9: 64 | C9: =(B9-B8)/B8 -> -0.072463768 | D9: Kurtosis | E9: -0.63331758 | F9: =(B9-E3)/E7 -> -1.6133282 | G9: =(B7+B8+B9)/3 -> 69.666667 | H9: =(B5+B6+B7+B8+B9)/5 -> 76
A10: 2023 | B10: 76 | C10: =(B10-B9)/B9 -> 0.1875 | D10: Skewness | E10: 0.046657948 | F10: =(B10-E3)/E7 -> -0.32266563 | G10: =(B8+B9+B10)/3 -> 69.666667 | H10: =(B6+B7+B8+B9+B10)/5 -> 73.4
A11: 2024 | B11: 73 | C11: =(B11-B10)/B10 -> -0.039473684 | D11: Range | E11: 30 | F11: =(B11-E3)/E7 -> -0.64533127 | G11: =(B9+B10+B11)/3 -> 71 | H11: =(B7+B8+B9+B10+B11)/5 -> 71.6
D12: Minimum | E12: 64
D13: Maximum | E13: 94
D14: Sum | E14: 790
D15: Count | E15: 10

Sheet Oxide ore grade processed(%)
A1: YEAR | B1: Oxide ore grade processed(%) | C1: Year on year growth | D1: Oxide ore grade processed(%) | F1: Z score for Oxide ore grade processed(%) | G1: Moving averages for 3 years | H1: Moving averages for 5 years
A2: 2015 | B2: 1.5 | F2: =(B2-E3)/E7 -> 1.1133615
A3: 2016 | B3: 1.5 | C3: =(B3-B2)/B2 -> 0 | D3: Mean | E3: 1.085 | F3: =(B3-E3)/E7 -> 1.1133615
A4: 2017 | B4: 1.5 | C4: =(B4-B3)/B3 -> 0 | D4: Standard Error | E4: 0.11787234 | F4: =(B4-E3)/E7 -> 1.1133615 | G4: =(B2+B3+B4)/3 -> 1.5
A5: 2018 | B5: 1.44 | C5: =(B5-B4)/B4 -> -0.04 | D5: Median | E5: 1.025 | F5: =(B5-E3)/E7 -> 0.95239354 | G5: =(B3+B4+B5)/3 -> 1.48
A6: 2019 | B6: 1.12 | C6: =(B6-B5)/B5 -> -0.22222222 | D6: Mode | E6: 1.5 | F6: =(B6-E3)/E7 -> 0.093897955 | G6: =(B4+B5+B6)/3 -> 1.3533333 | H6: =(B2+B3+B4+B5+B6)/5 -> 1.412
A7: 2020 | B7: 0.93 | C7: =(B7-B6)/B6 -> -0.16964286 | D7: Standard Deviation | E7: 0.37274507 | F7: =(B7-E3)/E7 -> -0.4158338 | G7: =(B5+B6+B7)/3 -> 1.1633333 | H7: =(B3+B4+B5+B6+B7)/5 -> 1.298
A8: 2021 | B8: 0.72 | C8: =(B8-B7)/B7 -> -0.22580645 | D8: Sample Variance | E8: 0.13893889 | F8: =(B8-E3)/E7 -> -0.97922153 | G8: =(B6+B7+B8)/3 -> 0.92333333 | H8: =(B4+B5+B6+B7+B8)/5 -> 1.142
A9: 2022 | B9: 0.57 | C9: =(B9-B8)/B8 -> -0.20833333 | D9: Kurtosis | E9: -1.9431322 | F9: =(B9-E3)/E7 -> -1.3816413 | G9: =(B7+B8+B9)/3 -> 0.74 | H9: =(B5+B6+B7+B8+B9)/5 -> 0.956
A10: 2023 | B10: 0.83 | C10: =(B10-B9)/B9 -> 0.45614035 | D10: Skewness | E10: 0.033831326 | F10: =(B10-E3)/E7 -> -0.68411367 | G10: =(B8+B9+B10)/3 -> 0.70666667 | H10: =(B6+B7+B8+B9+B10)/5 -> 0.834
A11: 2024 | B11: 0.74 | C11: =(B11-B10)/B10 -> -0.10843373 | D11: Range | E11: 0.93 | F11: =(B11-E3)/E7 -> -0.92556556 | G11: =(B9+B10+B11)/3 -> 0.71333333 | H11: =(B7+B8+B9+B10+B11)/5 -> 0.758
D12: Minimum | E12: 0.57
D13: Maximum | E13: 1.5
D14: Sum | E14: 10.85
D15: Count | E15: 10

Sheet Oxide ore tonnes milled(000's)
A1: YEAR | B1: Oxide ore tonnes milled(000's) | C1: Year on year growth | D1: Oxide ore tonnes milled(000's) | F1: Z score for Oxide ore tonnes milled(000's) | G1: Moving averages for 3 years | H1: Moving averages for 5years
A2: 2015 | B2: 6795 | F2: =(B2-E3)/E7 -> -1.2941375
A3: 2016 | B3: 7076 | C3: =(B3+B2)/B2 -> 2.0413539 | D3: Mean | E3: 7201 | F3: =(B3-E3)/E7 -> -0.39844136
A4: 2017 | B4: 6916 | C4: =(B4+B3)/B3 -> 1.9773884 | D4: Standard Error | E4: 99.207751 | F4: =(B4-E3)/E7 -> -0.90844629 | G4: =(B2+B3+B4)/3 -> 6929
A5: 2018 | B5: 6916 | C5: =(B5+B4)/B4 -> 2 | D5: Median | E5: 7182.5 | F5: =(B5-E3)/E7 -> -0.90844629 | G5: =(B3+B4+B5)/3 -> 6969.3333
A6: 2019 | B6: 7201 | C6: =(B6+B5)/B5 -> 2.0412088 | D6: Mode | E6: 6916 | F6: =(B6-E3)/E7 -> 0 | G6: =(B4+B5+B6)/3 -> 7011 | H6: =(B2+B3+B4+B5+B6)/5 -> 6980.8
A7: 2020 | B7: 7440 | C7: =(B7+B6)/B6 -> 2.0331898 | D7: Standard Deviation | E7: 313.72245 | F7: =(B7-E3)/E7 -> 0.76181987 | G7: =(B5+B6+B7)/3 -> 7185.6667 | H7: =(B3+B4+B5+B6+B7)/5 -> 7109.8
A8: 2021 | B8: 7164 | C8: =(B8+B7)/B7 -> 1.9629032 | D8: Sample Variance | E8: 98421.778 | F8: =(B8-E3)/E7 -> -0.11793864 | G8: =(B6+B7+B8)/3 -> 7268.3333 | H8: =(B4+B5+B6+B7+B8)/5 -> 7127.4
A9: 2022 | B9: 7866 | C9: =(B9+B8)/B8 -> 2.0979899 | D9: Kurtosis | E9: 1.0937581 | F9: =(B9-E3)/E7 -> 2.119708 | G9: =(B7+B8+B9)/3 -> 7490 | H9: =(B5+B6+B7+B8+B9)/5 -> 7317.4
A10: 2023 | B10: 7232 | C10: =(B10+B9)/B9 -> 1.9193999 | D10: Skewness | E10: 0.90367753 | F10: =(B10-E3)/E7 -> 0.098813456 | G10: =(B8+B9+B10)/3 -> 7420.6667 | H10: =(B6+B7+B8+B9+B10)/5 -> 7380.6
A11: 2024 | B11: 7404 | C11: =(B11+B10)/B10 -> 2.0237832 | D11: Range | E11: 1071 | F11: =(B11-E3)/E7 -> 0.64706876 | G11: =(B9+B10+B11)/3 -> 7500.6667 | H11: =(B7+B8+B9+B10+B11)/5 -> 7421.2
D12: Minimum | E12: 6795
D13: Maximum | E13: 7866
D14: Sum | E14: 72010
D15: Count | E15: 10

Sheet Mixed copper recovery(%)
A1: YEAR | B1: Mixed copper recovery(%) | C1: Year on year growth | D1: Mixed copper recovery(%) | F1: Z score for Mixed copper recovery(%) | G1: Moving averages for 3 years | H1: Moving averages for 5 years
A2: 2015 | B2: 72 | F2: =(B2-E3)/E7 -> -1.3681933
A3: 2016 | B3: 84 | C3: =(B3-B2)/B2 -> 0.16666667 | D3: Mean | E3: 78.9 | F3: =(B3-E3)/E7 -> 1.0112733
A4: 2017 | B4: 85 | C4: =(B4-B3)/B3 -> 0.011904762 | D4: Standard Error | E4: 1.5947832 | F4: =(B4-E3)/E7 -> 1.2095622 | G4: =(B2+B3+B4)/3 -> 80.333333
A5: 2018 | B5: 82 | C5: =(B5-B4)/B4 -> -0.035294118 | D5: Median | E5: 81 | F5: =(B5-E3)/E7 -> 0.61469553 | G5: =(B3+B4+B5)/3 -> 83.666667
A6: 2019 | B6: 77 | C6: =(B6-B5)/B5 -> -0.06097561 | D6: Mode | E6: 82 | F6: =(B6-E3)/E7 -> -0.37674887 | G6: =(B4+B5+B6)/3 -> 81.333333 | H6: =(B2+B3+B4+B5+B6)/5 -> 80
A7: 2020 | B7: 81 | C7: =(B7-B6)/B6 -> 0.051948052 | D7: Standard Deviation | E7: 5.0431472 | F7: =(B7-E3)/E7 -> 0.41640665 | G7: =(B5+B6+B7)/3 -> 80 | H7: =(B3+B4+B5+B6+B7)/5 -> 81.8
A8: 2021 | B8: 82 | C8: =(B8-B7)/B7 -> 0.012345679 | D8: Sample Variance | E8: 25.433333 | F8: =(B8-E3)/E7 -> 0.61469553 | G8: =(B6+B7+B8)/3 -> 80 | H8: =(B4+B5+B6+B7+B8)/5 -> 81.4
A9: 2022 | B9: 74 | C9: =(B9-B8)/B8 -> -0.097560976 | D9: Kurtosis | E9: -1.2904868 | F9: =(B9-E3)/E7 -> -0.97161551 | G9: =(B7+B8+B9)/3 -> 79 | H9: =(B5+B6+B7+B8+B9)/5 -> 79.2
A10: 2023 | B10: 71 | C10: =(B10-B9)/B9 -> -0.040540541 | D10: Skewness | E10: -0.55042706 | F10: =(B10-E3)/E7 -> -1.5664821 | G10: =(B8+B9+B10)/3 -> 75.666667 | H10: =(B6+B7+B8+B9+B10)/5 -> 77
A11: 2024 | B11: 81 | C11: =(B11-B10)/B10 -> 0.14084507 | D11: Range | E11: 14 | F11: =(B11-E3)/E7 -> 0.41640665 | G11: =(B9+B10+B11)/3 -> 75.333333 | H11: =(B7+B8+B9+B10+B11)/5 -> 77.8
D12: Minimum | E12: 71
D13: Maximum | E13: 85
D14: Sum | E14: 789
D15: Count | E15: 10

Sheet Mixed ore grade processed(%)
A1: YEAR | B1: Mixed ore grade processed(%) | C1: Year on year growth | D1: Mixed ore grade processed(%) | F1: Z score for Mixed ore grade processed(%) | G1: Moving averages for 3 years | H1: Moving averages for 5 years
A2: 2015 | B2: 1.1 | F2: =(B2-E3)/E7 -> 0.94075338
A3: 2016 | B3: 1 | C3: =(B3-B2)/B2 -> -0.090909091 | D3: Mean | E3: 0.941 | F3: =(B3-E3)/E7 -> 0.34908459
A4: 2017 | B4: 1 | C4: =(B4-B3)/B3 -> 0 | D4: Standard Error | E4: 0.053446754 | F4: =(B4-E3)/E7 -> 0.34908459 | G4: =(B2+B3+B4)/3 -> 1.0333333
A5: 2018 | B5: 1.06 | C5: =(B5-B4)/B4 -> 0.06 | D5: Median | E5: 1 | F5: =(B5-E3)/E7 -> 0.70408586 | G5: =(B3+B4+B5)/3 -> 1.02
A6: 2019 | B6: 1.05 | C6: =(B6-B5)/B5 -> -0.0094339623 | D6: Mode | E6: 1 | F6: =(B6-E3)/E7 -> 0.64491898 | G6: =(B4+B5+B6)/3 -> 1.0366667 | H6: =(B2+B3+B4+B5+B6)/5 -> 1.042
A7: 2020 | B7: 1 | C7: =(B7-B6)/B6 -> -0.047619048 | D7: Standard Deviation | E7: 0.16901348 | F7: =(B7-E3)/E7 -> 0.34908459 | G7: =(B5+B6+B7)/3 -> 1.0366667 | H7: =(B3+B4+B5+B6+B7)/5 -> 1.022
A8: 2021 | B8: 0.96 | C8: =(B8-B7)/B7 -> -0.04 | D8: Sample Variance | E8: 0.028565556 | F8: =(B8-E3)/E7 -> 0.11241707 | G8: =(B6+B7+B8)/3 -> 1.0033333 | H8: =(B4+B5+B6+B7+B8)/5 -> 1.014
A9: 2022 | B9: 0.63 | C9: =(B9-B8)/B8 -> -0.34375 | D9: Kurtosis | E9: 0.93779007 | F9: =(B9-E3)/E7 -> -1.8400899 | G9: =(B7+B8+B9)/3 -> 0.86333333 | H9: =(B5+B6+B7+B8+B9)/5 -> 0.94
A10: 2023 | B10: 0.63 | C10: =(B10-B9)/B9 -> 0 | D10: Skewness | E10: -1.5096737 | F10: =(B10-E3)/E7 -> -1.8400899 | G10: =(B8+B9+B10)/3 -> 0.74 | H10: =(B6+B7+B8+B9+B10)/5 -> 0.854
A11: 2024 | B11: 0.98 | C11: =(B11-B10)/B10 -> 0.55555556 | D11: Range | E11: 0.47 | F11: =(B11-E3)/E7 -> 0.23075083 | G11: =(B9+B10+B11)/3 -> 0.74666667 | H11: =(B7+B8+B9+B10+B11)/5 -> 0.84
D12: Minimum | E12: 0.63
D13: Maximum | E13: 1.1
D14: Sum | E14: 9.41
D15: Count | E15: 10

Sheet Sulphide copper recovery(%)
A1: YEAR | B1: Sulphide copper recovery(%) | C1: Year on year growth | D1: Sulphide copper recovery(%) | F1: Z score for Sulphide copper recovery(%) | G1: Moving averages for 3 years | H1: Moving averages for 5 years
A2: 2015 | B2: 91 | F2: =(B2-E3)/E7 -> 0.23968064
A3: 2016 | B3: 92 | C3: =(B3-B2)/B2 -> 0.010989011 | D3: Mean | E3: 90.7 | F3: =(B3-E3)/E7 -> 1.0386161
A4: 2017 | B4: 91 | C4: =(B4-B3)/B3 -> -0.010869565 | D4: Standard Error | E4: 0.3958114 | F4: =(B4-E3)/E7 -> 0.23968064 | G4: =(B2+B3+B4)/3 -> 91.333333
A5: 2018 | B5: 91 | C5: =(B5-B4)/B4 -> 0 | D5: Median | E5: 91 | F5: =(B5-E3)/E7 -> 0.23968064 | G5: =(B3+B4+B5)/3 -> 91.333333
A6: 2019 | B6: 91 | C6: =(B6-B5)/B5 -> 0 | D6: Mode | E6: 91 | F6: =(B6-E3)/E7 -> 0.23968064 | G6: =(B4+B5+B6)/3 -> 91 | H6: =(B2+B3+B4+B5+B6)/5 -> 91.2
A7: 2020 | B7: 92 | C7: =(B7-B6)/B6 -> 0.010989011 | D7: Standard Deviation | E7: 1.2516656 | F7: =(B7-E3)/E7 -> 1.0386161 | G7: =(B5+B6+B7)/3 -> 91.333333 | H7: =(B3+B4+B5+B6+B7)/5 -> 91.4
A8: 2021 | B8: 91 | C8: =(B8-B7)/B7 -> -0.010869565 | D8: Sample Variance | E8: 1.5666667 | F8: =(B8-E3)/E7 -> 0.23968064 | G8: =(B6+B7+B8)/3 -> 91.333333 | H8: =(B4+B5+B6+B7+B8)/5 -> 91.2
A9: 2022 | B9: 89 | C9: =(B9-B8)/B8 -> -0.021978022 | D9: Kurtosis | E9: 1.6413374 | F9: =(B9-E3)/E7 -> -1.3581903 | G9: =(B7+B8+B9)/3 -> 90.666667 | H9: =(B5+B6+B7+B8+B9)/5 -> 90.8
A10: 2023 | B10: 88 | C10: =(B10-B9)/B9 -> -0.011235955 | D10: Skewness | E10: -1.4193853 | F10: =(B10-E3)/E7 -> -2.1571257 | G10: =(B8+B9+B10)/3 -> 89.333333 | H10: =(B6+B7+B8+B9+B10)/5 -> 90.2
A11: 2024 | B11: 91 | C11: =(B11-B10)/B10 -> 0.034090909 | D11: Range | E11: 4 | F11: =(B11-E3)/E7 -> 0.23968064 | G11: =(B9+B10+B11)/3 -> 89.333333 | H11: =(B7+B8+B9+B10+B11)/5 -> 90.2
D12: Minimum | E12: 88
D13: Maximum | E13: 92
D14: Sum | E14: 907
D15: Count | E15: 10

Sheet Mixed ore tonnes milled(000's)
A1: YEAR | B1: Mixed ore tonnes milled(000's) | C1: Year on year growth | D1: Mixed ore tonnes milled(000's) | F1: Z score for Mixed ore tonnes milled(000's) | G1: Moving averages for 3 years | H1: Moving averages for 5 years
A2: 2015 | B2: 10949 | F2: =(B2-E3)/E7 -> 2.2257451
A3: 2016 | B3: 7953 | C3: =(B3-B2)/B2 -> -0.2736323 | D3: Mean | E3: 8409.9 | F3: =(B3-E3)/E7 -> -0.40051315
A4: 2017 | B4: 7997 | C4: =(B4-B3)/B3 -> 0.0055325035 | D4: Standard Error | E4: 360.74837 | F4: =(B4-E3)/E7 -> -0.36194327 | G4: =(B2+B3+B4)/3 -> 8966.3333
A5: 2018 | B5: 8186 | C5: =(B5-B4)/B4 -> 0.023633863 | D5: Median | E5: 7975 | F5: =(B5-E3)/E7 -> -0.1962681 | G5: =(B3+B4+B5)/3 -> 8045.3333
A6: 2019 | B6: 7699 | C6: =(B6-B5)/B5 -> -0.059491815 | D6: Mode | E6: #N/A | F6: =(B6-E3)/E7 -> -0.62316655 | G6: =(B4+B5+B6)/3 -> 7960.6667 | H6: =(B2+B3+B4+B5+B6)/5 -> 8556.8
A7: 2020 | B7: 8167 | C7: =(B7-B6)/B6 -> 0.060787115 | D7: Standard Deviation | E7: 1140.7865 | F7: =(B7-E3)/E7 -> -0.21292327 | G7: =(B5+B6+B7)/3 -> 8017.3333 | H7: =(B3+B4+B5+B6+B7)/5 -> 8000.4
A8: 2021 | B8: 7601 | C8: =(B8-B7)/B7 -> -0.069303294 | D8: Sample Variance | E8: 1301393.9 | F8: =(B8-E3)/E7 -> -0.7090722 | G8: =(B6+B7+B8)/3 -> 7822.3333 | H8: =(B4+B5+B6+B7+B8)/5 -> 7930
A9: 2022 | B9: 7713 | C9: =(B9-B8)/B8 -> 0.014734903 | D9: Kurtosis | E9: 2.1245424 | F9: =(B9-E3)/E7 -> -0.61089432 | G9: =(B7+B8+B9)/3 -> 7827 | H9: =(B5+B6+B7+B8+B9)/5 -> 7873.2
A10: 2023 | B10: 7773 | C10: =(B10-B9)/B9 -> 0.0077790743 | D10: Skewness | E10: 1.7956486 | F10: =(B10-E3)/E7 -> -0.55829902 | G10: =(B8+B9+B10)/3 -> 7695.6667 | H10: =(B6+B7+B8+B9+B10)/5 -> 7790.6
A11: 2024 | B11: 10061 | C11: =(B11-B10)/B10 -> 0.29435224 | D11: Range | E11: 3348 | F11: =(B11-E3)/E7 -> 1.4473348 | G11: =(B9+B10+B11)/3 -> 8515.6667 | H11: =(B7+B8+B9+B10+B11)/5 -> 8263
D12: Minimum | E12: 7601
D13: Maximum | E13: 10949
D14: Sum | E14: 84099
D15: Count | E15: 10

Sheet Sulphide ore grade processed(%)
A1: YEAR | B1: Sulphide ore grade processed(%) | C1: Year on year growth | D1: Sulphide ore grade processed(%) | F1: Z score for Sulphide ore grade processed(%) | G1: Moving averages 3 years | H1: Moving averages 5 years
A2: 2015 | B2: 0.8 | F2: =(B2-E3)/E7 -> 0.33028913
A3: 2016 | B3: 0.8 | C3: =(B3-B2)/B2 -> 0 | D3: Mean | E3: 0.76 | F3: =(B3-E3)/E7 -> 0.33028913
A4: 2017 | B4: 0.8 | C4: =(B4-B3)/B3 -> 0 | D4: Standard Error | E4: 0.038297084 | F4: =(B4-E3)/E7 -> 0.33028913 | G4: =(B2+B3+B4)/3 -> 0.8
A5: 2018 | B5: 0.78 | C5: =(B5-B4)/B4 -> -0.025 | D5: Median | E5: 0.8 | F5: =(B5-E3)/E7 -> 0.16514456 | G5: =(B3+B4+B5)/3 -> 0.79333333
A6: 2019 | B6: 0.89 | C6: =(B6-B5)/B5 -> 0.14102564 | D6: Mode | E6: 0.8 | F6: =(B6-E3)/E7 -> 1.0734397 | G6: =(B4+B5+B6)/3 -> 0.82333333 | H6: =(B2+B3+B4+B5+B6)/5 -> 0.814
A7: 2020 | B7: 0.83 | C7: =(B7-B6)/B6 -> -0.06741573 | D7: Standard Deviation | E7: 0.12110601 | F7: =(B7-E3)/E7 -> 0.57800598 | G7: =(B5+B6+B7)/3 -> 0.83333333 | H7: =(B3+B4+B5+B6+B7)/5 -> 0.82
A8: 2021 | B8: 0.88 | C8: =(B8-B7)/B7 -> 0.060240964 | D8: Sample Variance | E8: 0.014666667 | F8: =(B8-E3)/E7 -> 0.99086739 | G8: =(B6+B7+B8)/3 -> 0.86666667 | H8: =(B4+B5+B6+B7+B8)/5 -> 0.836
A9: 2022 | B9: 0.71 | C9: =(B9-B8)/B8 -> -0.19318182 | D9: Kurtosis | E9: 0.82780032 | F9: =(B9-E3)/E7 -> -0.41286141 | G9: =(B7+B8+B9)/3 -> 0.80666667 | H9: =(B5+B6+B7+B8+B9)/5 -> 0.818
A10: 2023 | B10: 0.51 | C10: =(B10-B9)/B9 -> -0.28169014 | D10: Skewness | E10: -1.2024589 | F10: =(B10-E3)/E7 -> -2.0643071 | G10: =(B8+B9+B10)/3 -> 0.7 | H10: =(B6+B7+B8+B9+B10)/5 -> 0.764
A11: 2024 | B11: 0.6 | C11: =(B11-B10)/B10 -> 0.17647059 | D11: Range | E11: 0.38 | F11: =(B11-E3)/E7 -> -1.3211565 | G11: =(B9+B10+B11)/3 -> 0.60666667 | H11: =(B7+B8+B9+B10+B11)/5 -> 0.706
D12: Minimum | E12: 0.51
D13: Maximum | E13: 0.89
D14: Sum | E14: 7.6
D15: Count | E15: 10

Sheet Sulphide ore Kansanshi
A1: YEAR | B1: Sulphide ore tonnes milled(000's) | C1: Year on year growth | D1: Sulphide ore tonnes milled(000's) | F1: Z Score for Sulphide ore tonnes milled(000's) | G1: Moving averages for 3 years | H1: Moving averages for 5 years.
A2: 2015 | B2: 8296 | F2: =(B2-E3)/E7 -> -2.1398609
A3: 2016 | B3: 11988 | C3: =(B3-B2)/B2 -> 0.44503375 | D3: Mean | E3: 12111.1 | F3: =(B3-E3)/E7 -> -0.069045865
A4: 2017 | B4: 12970 | C4: =(B4-B3)/B3 -> 0.081915249 | D4: Standard Error | E4: 563.7939 | F4: =(B4-E3)/E7 -> 0.48175056 | G4: =(B2+B3+B4)/3 -> 11084.667
A5: 2018 | B5: 12978 | C5: =(B5-B4)/B4 -> 0.00061680802 | D5: Median | E5: 12939 | F5: =(B5-E3)/E7 -> 0.4862377 | G5: =(B3+B4+B5)/3 -> 12645.333
A6: 2019 | B6: 12908 | C6: =(B6-B5)/B5 -> -0.0053937433 | D6: Mode | E6: #N/A | F6: =(B6-E3)/E7 -> 0.44697522 | G6: =(B4+B5+B6)/3 -> 12952 | H6: =(B2+B3+B4+B5+B6)/5 -> 11828
A7: 2020 | B7: 13527 | C7: =(B7-B6)/B6 -> 0.047954757 | D7: Standard Deviation | E7: 1782.8729 | F7: =(B7-E3)/E7 -> 0.79416768 | G7: =(B5+B6+B7)/3 -> 13137.667 | H7: =(B3+B4+B5+B6+B7)/5 -> 12874.2
A8: 2021 | B8: 13386 | C8: =(B8-B7)/B7 -> -0.010423597 | D8: Sample Variance | E8: 3178635.7 | F8: =(B8-E3)/E7 -> 0.71508183 | G8: =(B6+B7+B8)/3 -> 13273.667 | H8: =(B4+B5+B6+B7+B8)/5 -> 13153.8
